<sdf version='1.4'>
  <world name='racecar_tunnel'>
    <light name='sun' type='directional'>
      <cast_shadows>1</cast_shadows>
      <pose>0 0 10 0 -0 0</pose>
      <diffuse>0.8 0.8 0.8 1</diffuse>
      <specular>0.2 0.2 0.2 1</specular>
      <attenuation>
        <range>1000</range>
        <constant>0.9</constant>
        <linear>0.01</linear>
        <quadratic>0.001</quadratic>
      </attenuation>
      <direction>-0.5 0.1 -0.9</direction>
    </light>
    <gui fullscreen='0'>
      <camera name='main'>
        <pose>-0.474957 -5.71636 16.3108 3.14159 1.57059 3.14159</pose>
        <view_controller>orbit</view_controller>
      </camera>
    </gui>
    <model name='ground_plane'>
      <static>1</static>
      <link name='link'>
        <collision name='collision'>
          <geometry>
            <plane>
              <normal>0 0 1</normal>
              <size>150 150</size>
            </plane>
          </geometry>
          <surface>
            <friction>
              <ode>
                <mu>100</mu>
                <mu2>50</mu2>
              </ode>
            </friction>
            <bounce/>
            <contact>
              <ode/>
            </contact>
          </surface>
          <max_contacts>10</max_contacts>
        </collision>
        <visual name='visual'>
          <cast_shadows>0</cast_shadows>
          <geometry>
            <plane>
              <normal>0 0 1</normal>
              <size>150 150</size>
            </plane>
          </geometry>
          <material>
            <script>
              <uri>file://media/materials/scripts/gazebo.material</uri>
              <name>Gazebo/Grey</name>
            </script>
          </material>
        </visual>
        <velocity_decay>
          <linear>0</linear>
          <angular>0</angular>
        </velocity_decay>
        <self_collide>0</self_collide>
        <kinematic>0</kinematic>
        <gravity>1</gravity>
      </link>
    </model>
    <model name='MIT_Tunnel'>
      <pose>6 20 0 0 -0 0</pose>
      <link name='Wall_10'>
        <collision name='Wall_10_Collision'>
          <geometry>
            <box>
              <size>32.6917 0.15 2.5</size>
            </box>
          </geometry>
          <pose>0 0 1.25 0 -0 0</pose>
          <max_contacts>10</max_contacts>
          <surface>
            <bounce/>
            <friction>
              <ode/>
            </friction>
            <contact>
              <ode/>
            </contact>
          </surface>
        </collision>
        <visual name='Wall_10_Visual'>
          <pose>0 0 1.25 0 -0 0</pose>
          <geometry>
            <box>
              <size>32.6917 0.15 2.5</size>
            </box>
          </geometry>
          <material>
            <script>
              <uri>file://media/materials/scripts/gazebo.material</uri>
              <name>Gazebo/CeilingTiled</name>
            </script>
            <ambient>1 1 1 1</ambient>
          </material>
        </visual>
        <pose>-19.1952 15.5558 0 0 0 -0.001042</pose>
        <velocity_decay>
          <linear>0</linear>
          <angular>0</angular>
        </velocity_decay>
        <self_collide>0</self_collide>
        <kinematic>0</kinematic>
        <gravity>1</gravity>
      </link>
      <link name='Wall_12'>
        <collision name='Wall_12_Collision'>
          <geometry>
            <box>
              <size>8.5 0.15 2.5</size>
            </box>
          </geometry>
          <pose>0 0 1.25 0 -0 0</pose>
          <max_contacts>10</max_contacts>
          <surface>
            <bounce/>
            <friction>
              <ode/>
            </friction>
            <contact>
              <ode/>
            </contact>
          </surface>
        </collision>
        <visual name='Wall_12_Visual'>
          <pose>0 0 1.25 0 -0 0</pose>
          <geometry>
            <box>
              <size>8.5 0.15 2.5</size>
            </box>
          </geometry>
          <material>
            <script>
              <uri>file://media/materials/scripts/gazebo.material</uri>
              <name>Gazebo/CeilingTiled</name>
            </script>
            <ambient>1 1 1 1</ambient>
          </material>
        </visual>
        <pose>-2.92483 11.3639 0 0 0 -1.5708</pose>
        <velocity_decay>
          <linear>0</linear>
          <angular>0</angular>
        </velocity_decay>
        <self_collide>0</self_collide>
        <kinematic>0</kinematic>
        <gravity>1</gravity>
      </link>
      <link name='Wall_15'>
        <collision name='Wall_15_Collision'>
          <geometry>
            <box>
              <size>18.75 0.15 2.5</size>
            </box>
          </geometry>
          <pose>0 0 1.25 0 -0 0</pose>
          <max_contacts>10</max_contacts>
          <surface>
            <bounce/>
            <friction>
              <ode/>
            </friction>
            <contact>
              <ode/>
            </contact>
          </surface>
        </collision>
        <visual name='Wall_15_Visual'>
          <pose>0 0 1.25 0 -0 0</pose>
          <geometry>
            <box>
              <size>18.75 0.15 2.5</size>
            </box>
          </geometry>
          <material>
            <script>
              <uri>file://media/materials/scripts/gazebo.material</uri>
              <name>Gazebo/CeilingTiled</name>
            </script>
            <ambient>1 1 1 1</ambient>
          </material>
        </visual>
        <pose>6.37517 7.18889 0 0 -0 0</pose>
        <velocity_decay>
          <linear>0</linear>
          <angular>0</angular>
        </velocity_decay>
        <self_collide>0</self_collide>
        <kinematic>0</kinematic>
        <gravity>1</gravity>
      </link>
      <link name='Wall_17'>
        <collision name='Wall_17_Collision'>
          <geometry>
            <box>
              <size>4.75 0.15 2.5</size>
            </box>
          </geometry>
          <pose>0 0 1.25 0 -0 0</pose>
          <max_contacts>10</max_contacts>
          <surface>
            <bounce/>
            <friction>
              <ode/>
            </friction>
            <contact>
              <ode/>
            </contact>
          </surface>
        </collision>
        <visual name='Wall_17_Visual'>
          <pose>0 0 1.25 0 -0 0</pose>
          <geometry>
            <box>
              <size>4.75 0.15 2.5</size>
            </box>
          </geometry>
          <material>
            <script>
              <uri>file://media/materials/scripts/gazebo.material</uri>
              <name>Gazebo/CeilingTiled</name>
            </script>
            <ambient>1 1 1 1</ambient>
          </material>
        </visual>
        <pose>15.0799 4.96726 0 0 0 -1.8326</pose>
        <velocity_decay>
          <linear>0</linear>
          <angular>0</angular>
        </velocity_decay>
        <self_collide>0</self_collide>
        <kinematic>0</kinematic>
        <gravity>1</gravity>
      </link>
      <link name='Wall_18'>
        <collision name='Wall_18_Collision'>
          <geometry>
            <box>
              <size>2.75 0.15 2.5</size>
            </box>
          </geometry>
          <pose>0 0 1.25 0 -0 0</pose>
          <max_contacts>10</max_contacts>
          <surface>
            <bounce/>
            <friction>
              <ode/>
            </friction>
            <contact>
              <ode/>
            </contact>
          </surface>
        </collision>
        <visual name='Wall_18_Visual'>
          <pose>0 0 1.25 0 -0 0</pose>
          <geometry>
            <box>
              <size>2.75 0.15 2.5</size>
            </box>
          </geometry>
          <material>
            <script>
              <uri>file://media/materials/scripts/gazebo.material</uri>
              <name>Gazebo/CeilingTiled</name>
            </script>
            <ambient>1 1 1 1</ambient>
          </material>
        </visual>
        <pose>13.1846 2.74563 0 0 -0 3.14159</pose>
        <velocity_decay>
          <linear>0</linear>
          <angular>0</angular>
        </velocity_decay>
        <self_collide>0</self_collide>
        <kinematic>0</kinematic>
        <gravity>1</gravity>
      </link>
      <link name='Wall_19'>
        <collision name='Wall_19_Collision'>
          <geometry>
            <box>
              <size>2.75 0.15 2.5</size>
            </box>
          </geometry>
          <pose>0 0 1.25 0 -0 0</pose>
          <max_contacts>10</max_contacts>
          <surface>
            <bounce/>
            <friction>
              <ode/>
            </friction>
            <contact>
              <ode/>
            </contact>
          </surface>
        </collision>
        <visual name='Wall_19_Visual'>
          <pose>0 0 1.25 0 -0 0</pose>
          <geometry>
            <box>
              <size>2.75 0.15 2.5</size>
            </box>
          </geometry>
          <material>
            <script>
              <uri>file://media/materials/scripts/gazebo.material</uri>
              <name>Gazebo/Grey</name>
            </script>
            <ambient>1 1 1 1</ambient>
          </material>
        </visual>
        <pose>10.9654 1.82639 0 0 0 -2.35619</pose>
        <velocity_decay>
          <linear>0</linear>
          <angular>0</angular>
        </velocity_decay>
        <self_collide>0</self_collide>
        <kinematic>0</kinematic>
        <gravity>1</gravity>
      </link>
      <link name='Wall_2'>
        <collision name='Wall_2_Collision'>
          <geometry>
            <box>
              <size>24.25 0.15 2.5</size>
            </box>
          </geometry>
          <pose>0 0 1.25 0 -0 0</pose>
          <max_contacts>10</max_contacts>
          <surface>
            <bounce/>
            <friction>
              <ode/>
            </friction>
            <contact>
              <ode/>
            </contact>
          </surface>
        </collision>
        <visual name='Wall_2_Visual'>
          <pose>0 0 1.25 0 -0 0</pose>
          <geometry>
            <box>
              <size>24.25 0.15 2.5</size>
            </box>
          </geometry>
          <material>
            <script>
              <uri>file://media/materials/scripts/gazebo.material</uri>
              <name>Gazebo/CeilingTiled</name>
            </script>
            <ambient>1 1 1 1</ambient>
          </material>
        </visual>
        <pose>-52.25 -18.2689 0 0 -0 0</pose>
        <velocity_decay>
          <linear>0</linear>
          <angular>0</angular>
        </velocity_decay>
        <self_collide>0</self_collide>
        <kinematic>0</kinematic>
        <gravity>1</gravity>
      </link>
      <link name='Wall_20'>
        <collision name='Wall_20_Collision'>
          <geometry>
            <box>
              <size>2.25 0.15 2.5</size>
            </box>
          </geometry>
          <pose>0 0 1.25 0 -0 0</pose>
          <max_contacts>10</max_contacts>
          <surface>
            <bounce/>
            <friction>
              <ode/>
            </friction>
            <contact>
              <ode/>
            </contact>
          </surface>
        </collision>
        <visual name='Wall_20_Visual'>
          <pose>0 0 1.25 0 -0 0</pose>
          <geometry>
            <box>
              <size>2.25 0.15 2.5</size>
            </box>
          </geometry>
          <material>
            <script>
              <uri>file://media/materials/scripts/gazebo.material</uri>
              <name>Gazebo/Grey</name>
            </script>
            <ambient>1 1 1 1</ambient>
          </material>
        </visual>
        <pose>10.0461 -0.142849 0 0 0 -1.5708</pose>
        <velocity_decay>
          <linear>0</linear>
          <angular>0</angular>
        </velocity_decay>
        <self_collide>0</self_collide>
        <kinematic>0</kinematic>
        <gravity>1</gravity>
      </link>
      <link name='Wall_22'>
        <collision name='Wall_22_Collision'>
          <geometry>
            <box>
              <size>5.08891 0.15 2.5</size>
            </box>
          </geometry>
          <pose>0 0 1.25 0 -0 0</pose>
          <max_contacts>10</max_contacts>
          <surface>
            <bounce/>
            <friction>
              <ode/>
            </friction>
            <contact>
              <ode/>
            </contact>
          </surface>
        </collision>
        <visual name='Wall_22_Visual'>
          <pose>0 0 1.25 0 -0 0</pose>
          <geometry>
            <box>
              <size>5.08891 0.15 2.5</size>
            </box>
          </geometry>
          <material>
            <script>
              <uri>file://media/materials/scripts/gazebo.material</uri>
              <name>Gazebo/CeilingTiled</name>
            </script>
            <ambient>1 1 1 1</ambient>
          </material>
        </visual>
        <pose>8.53852 -3.14869 0 0 0 -2.22749</pose>
        <velocity_decay>
          <linear>0</linear>
          <angular>0</angular>
        </velocity_decay>
        <self_collide>0</self_collide>
        <kinematic>0</kinematic>
        <gravity>1</gravity>
      </link>
      <link name='Wall_23'>
        <collision name='Wall_23_Collision'>
          <geometry>
            <box>
              <size>1.75 0.15 2.5</size>
            </box>
          </geometry>
          <pose>0 0 1.25 0 -0 0</pose>
          <max_contacts>10</max_contacts>
          <surface>
            <bounce/>
            <friction>
              <ode/>
            </friction>
            <contact>
              <ode/>
            </contact>
          </surface>
        </collision>
        <visual name='Wall_23_Visual'>
          <pose>0 0 1.25 0 -0 0</pose>
          <geometry>
            <box>
              <size>1.75 0.15 2.5</size>
            </box>
          </geometry>
          <material>
            <script>
              <uri>file://media/materials/scripts/gazebo.material</uri>
              <name>Gazebo/CeilingTiled</name>
            </script>
            <ambient>1 1 1 1</ambient>
          </material>
        </visual>
        <pose>6.23091 -5.10454 0 0 -0 3.14159</pose>
        <velocity_decay>
          <linear>0</linear>
          <angular>0</angular>
        </velocity_decay>
        <self_collide>0</self_collide>
        <kinematic>0</kinematic>
        <gravity>1</gravity>
      </link>
      <link name='Wall_24'>
        <collision name='Wall_24_Collision'>
          <geometry>
            <box>
              <size>2.59216 0.15 2.5</size>
            </box>
          </geometry>
          <pose>0 0 1.25 0 -0 0</pose>
          <max_contacts>10</max_contacts>
          <surface>
            <bounce/>
            <friction>
              <ode/>
            </friction>
            <contact>
              <ode/>
            </contact>
          </surface>
        </collision>
        <visual name='Wall_24_Visual'>
          <pose>0 0 1.25 0 -0 0</pose>
          <geometry>
            <box>
              <size>2.59216 0.15 2.5</size>
            </box>
          </geometry>
          <material>
            <script>
              <uri>file://media/materials/scripts/gazebo.material</uri>
              <name>Gazebo/CeilingTiled</name>
            </script>
            <ambient>1 1 1 1</ambient>
          </material>
        </visual>
        <pose>4.6163 -6.01417 0 0 0 -2.30114</pose>
        <velocity_decay>
          <linear>0</linear>
          <angular>0</angular>
        </velocity_decay>
        <self_collide>0</self_collide>
        <kinematic>0</kinematic>
        <gravity>1</gravity>
      </link>
      <link name='Wall_26'>
        <collision name='Wall_26_Collision'>
          <geometry>
            <box>
              <size>3 0.15 2.5</size>
            </box>
          </geometry>
          <pose>0 0 1.25 0 -0 0</pose>
          <max_contacts>10</max_contacts>
          <surface>
            <bounce/>
            <friction>
              <ode/>
            </friction>
            <contact>
              <ode/>
            </contact>
          </surface>
        </collision>
        <visual name='Wall_26_Visual'>
          <pose>0 0 1.25 0 -0 0</pose>
          <geometry>
            <box>
              <size>3 0.15 2.5</size>
            </box>
          </geometry>
          <material>
            <script>
              <uri>file://media/materials/scripts/gazebo.material</uri>
              <name>Gazebo/Grey</name>
            </script>
            <ambient>1 1 1 1</ambient>
          </material>
        </visual>
        <pose>3.80168 -8.34882 0 0 0 -1.5708</pose>
        <velocity_decay>
          <linear>0</linear>
          <angular>0</angular>
        </velocity_decay>
        <self_collide>0</self_collide>
        <kinematic>0</kinematic>
        <gravity>1</gravity>
      </link>
      <link name='Wall_27'>
        <collision name='Wall_27_Collision'>
          <geometry>
            <box>
              <size>2.5 0.15 2.5</size>
            </box>
          </geometry>
          <pose>0 0 1.25 0 -0 0</pose>
          <max_contacts>10</max_contacts>
          <surface>
            <bounce/>
            <friction>
              <ode/>
            </friction>
            <contact>
              <ode/>
            </contact>
          </surface>
        </collision>
        <visual name='Wall_27_Visual'>
          <pose>0 0 1.25 0 -0 0</pose>
          <geometry>
            <box>
              <size>2.5 0.15 2.5</size>
            </box>
          </geometry>
          <material>
            <script>
              <uri>file://media/materials/scripts/gazebo.material</uri>
              <name>Gazebo/CeilingTiled</name>
            </script>
            <ambient>1 1 1 1</ambient>
          </material>
        </visual>
        <pose>2.62668 -9.77382 0 0 -0 3.14159</pose>
        <velocity_decay>
          <linear>0</linear>
          <angular>0</angular>
        </velocity_decay>
        <self_collide>0</self_collide>
        <kinematic>0</kinematic>
        <gravity>1</gravity>
      </link>
      <link name='Wall_28'>
        <collision name='Wall_28_Collision'>
          <geometry>
            <box>
              <size>4.15096 0.15 2.5</size>
            </box>
          </geometry>
          <pose>0 0 1.25 0 -0 0</pose>
          <max_contacts>10</max_contacts>
          <surface>
            <bounce/>
            <friction>
              <ode/>
            </friction>
            <contact>
              <ode/>
            </contact>
          </surface>
        </collision>
        <visual name='Wall_28_Visual'>
          <pose>0 0 1.25 0 -0 0</pose>
          <geometry>
            <box>
              <size>4.15096 0.15 2.5</size>
            </box>
          </geometry>
          <material>
            <script>
              <uri>file://media/materials/scripts/gazebo.material</uri>
              <name>Gazebo/CeilingTiled</name>
            </script>
            <ambient>1 1 1 1</ambient>
          </material>
        </visual>
        <pose>0.152007 -11.2946 0 0 0 -2.27796</pose>
        <velocity_decay>
          <linear>0</linear>
          <angular>0</angular>
        </velocity_decay>
        <self_collide>0</self_collide>
        <kinematic>0</kinematic>
        <gravity>1</gravity>
      </link>
      <link name='Wall_29'>
        <collision name='Wall_29_Collision'>
          <geometry>
            <box>
              <size>5.87777 0.15 2.5</size>
            </box>
          </geometry>
          <pose>0 0 1.25 0 -0 0</pose>
          <max_contacts>10</max_contacts>
          <surface>
            <bounce/>
            <friction>
              <ode/>
            </friction>
            <contact>
              <ode/>
            </contact>
          </surface>
        </collision>
        <visual name='Wall_29_Visual'>
          <pose>0 0 1.25 0 -0 0</pose>
          <geometry>
            <box>
              <size>5.87777 0.15 2.5</size>
            </box>
          </geometry>
          <material>
            <script>
              <uri>file://media/materials/scripts/gazebo.material</uri>
              <name>Gazebo/CeilingTiled</name>
            </script>
            <ambient>1 1 1 1</ambient>
          </material>
        </visual>
        <pose>-1.14312 -15.679 0 0 0 -1.56921</pose>
        <velocity_decay>
          <linear>0</linear>
          <angular>0</angular>
        </velocity_decay>
        <self_collide>0</self_collide>
        <kinematic>0</kinematic>
        <gravity>1</gravity>
      </link>
      <link name='Wall_30'>
        <collision name='Wall_30_Collision'>
          <geometry>
            <box>
              <size>65.5 0.15 2.5</size>
            </box>
          </geometry>
          <pose>0 0 1.25 0 -0 0</pose>
          <max_contacts>10</max_contacts>
          <surface>
            <bounce/>
            <friction>
              <ode/>
            </friction>
            <contact>
              <ode/>
            </contact>
          </surface>
        </collision>
        <visual name='Wall_30_Visual'>
          <pose>0 0 1.25 0 -0 0</pose>
          <geometry>
            <box>
              <size>65.5 0.15 2.5</size>
            </box>
          </geometry>
          <material>
            <script>
              <uri>file://media/materials/scripts/gazebo.material</uri>
              <name>Gazebo/CeilingTiled</name>
            </script>
            <ambient>1 1 1 1</ambient>
          </material>
        </visual>
        <pose>31.5103 -18.5427 0 0 -0 0</pose>
        <velocity_decay>
          <linear>0</linear>
          <angular>0</angular>
        </velocity_decay>
        <self_collide>0</self_collide>
        <kinematic>0</kinematic>
        <gravity>1</gravity>
      </link>
      <link name='Wall_32'>
        <collision name='Wall_32_Collision'>
          <geometry>
            <box>
              <size>4.75 0.15 2.5</size>
            </box>
          </geometry>
          <pose>0 0 1.25 0 -0 0</pose>
          <max_contacts>10</max_contacts>
          <surface>
            <bounce/>
            <friction>
              <ode/>
            </friction>
            <contact>
              <ode/>
            </contact>
          </surface>
        </collision>
        <visual name='Wall_32_Visual'>
          <pose>0 0 1.25 0 -0 0</pose>
          <geometry>
            <box>
              <size>4.75 0.15 2.5</size>
            </box>
          </geometry>
          <material>
            <script>
              <uri>file://media/materials/scripts/gazebo.material</uri>
              <name>Gazebo/Grey</name>
            </script>
            <ambient>1 1 1 1</ambient>
          </material>
        </visual>
        <pose>64.1853 -20.8427 0 0 0 -1.5708</pose>
        <velocity_decay>
          <linear>0</linear>
          <angular>0</angular>
        </velocity_decay>
        <self_collide>0</self_collide>
        <kinematic>0</kinematic>
        <gravity>1</gravity>
      </link>
      <link name='Wall_34'>
        <collision name='Wall_34_Collision'>
          <geometry>
            <box>
              <size>5 0.15 2.5</size>
            </box>
          </geometry>
          <pose>0 0 1.25 0 -0 0</pose>
          <max_contacts>10</max_contacts>
          <surface>
            <bounce/>
            <friction>
              <ode/>
            </friction>
            <contact>
              <ode/>
            </contact>
          </surface>
        </collision>
        <visual name='Wall_34_Visual'>
          <pose>0 0 1.25 0 -0 0</pose>
          <geometry>
            <box>
              <size>5 0.15 2.5</size>
            </box>
          </geometry>
          <material>
            <script>
              <uri>file://media/materials/scripts/gazebo.material</uri>
              <name>Gazebo/CeilingTiled</name>
            </script>
            <ambient>1 1 1 1</ambient>
          </material>
        </visual>
        <pose>-64.3 -20.6939 0 0 0 -1.5708</pose>
        <velocity_decay>
          <linear>0</linear>
          <angular>0</angular>
        </velocity_decay>
        <self_collide>0</self_collide>
        <kinematic>0</kinematic>
        <gravity>1</gravity>
      </link>
      <link name='Wall_35'>
        <collision name='Wall_35_Collision'>
          <geometry>
            <box>
              <size>128.75 0.15 2.5</size>
            </box>
          </geometry>
          <pose>0 0 1.25 0 -0 0</pose>
          <max_contacts>10</max_contacts>
          <surface>
            <bounce/>
            <friction>
              <ode/>
            </friction>
            <contact>
              <ode/>
            </contact>
          </surface>
        </collision>
        <visual name='Wall_35_Visual'>
          <pose>0 0 1.25 0 -0 0</pose>
          <geometry>
            <box>
              <size>128.75 0.15 2.5</size>
            </box>
          </geometry>
          <material>
            <script>
              <uri>file://media/materials/scripts/gazebo.material</uri>
              <name>Gazebo/CeilingTiled</name>
            </script>
            <ambient>1 1 1 1</ambient>
          </material>
        </visual>
        <pose>1e-06 -23.1189 0 0 -0 0</pose>
        <velocity_decay>
          <linear>0</linear>
          <angular>0</angular>
        </velocity_decay>
        <self_collide>0</self_collide>
        <kinematic>0</kinematic>
        <gravity>1</gravity>
      </link>
      <link name='Wall_37'>
        <collision name='Wall_37_Collision'>
          <geometry>
            <box>
              <size>4.75 0.15 2.5</size>
            </box>
          </geometry>
          <pose>0 0 1.25 0 -0 0</pose>
          <max_contacts>10</max_contacts>
          <surface>
            <bounce/>
            <friction>
              <ode/>
            </friction>
            <contact>
              <ode/>
            </contact>
          </surface>
        </collision>
        <visual name='Wall_37_Visual'>
          <pose>0 0 1.25 0 -0 0</pose>
          <geometry>
            <box>
              <size>4.75 0.15 2.5</size>
            </box>
          </geometry>
          <material>
            <script>
              <uri>file://media/materials/scripts/gazebo.material</uri>
              <name>Gazebo/CeilingTiled</name>
            </script>
            <ambient>1 1 1 1</ambient>
          </material>
        </visual>
        <pose>-37.9 23.0811 0 0 -0 0</pose>
        <velocity_decay>
          <linear>0</linear>
          <angular>0</angular>
        </velocity_decay>
        <self_collide>0</self_collide>
        <kinematic>0</kinematic>
        <gravity>1</gravity>
      </link>
      <link name='Wall_41'>
        <collision name='Wall_41_Collision'>
          <geometry>
            <box>
              <size>31.75 0.15 2.5</size>
            </box>
          </geometry>
          <pose>0 0 1.25 0 -0 0</pose>
          <max_contacts>10</max_contacts>
          <surface>
            <bounce/>
            <friction>
              <ode/>
            </friction>
            <contact>
              <ode/>
            </contact>
          </surface>
        </collision>
        <visual name='Wall_41_Visual'>
          <pose>0 0 1.25 0 -0 0</pose>
          <geometry>
            <box>
              <size>31.75 0.15 2.5</size>
            </box>
          </geometry>
          <material>
            <script>
              <uri>file://media/materials/scripts/gazebo.material</uri>
              <name>Gazebo/CeilingTiled</name>
            </script>
            <ambient>1 1 1 1</ambient>
          </material>
        </visual>
        <pose>-35.4175 -2.72616 0 0 -0 1.5708</pose>
        <velocity_decay>
          <linear>0</linear>
          <angular>0</angular>
        </velocity_decay>
        <self_collide>0</self_collide>
        <kinematic>0</kinematic>
        <gravity>1</gravity>
      </link>
      <link name='Wall_43'>
        <collision name='Wall_43_Collision'>
          <geometry>
            <box>
              <size>30 0.15 2.5</size>
            </box>
          </geometry>
          <pose>0 0 1.25 0 -0 0</pose>
          <max_contacts>10</max_contacts>
          <surface>
            <bounce/>
            <friction>
              <ode/>
            </friction>
            <contact>
              <ode/>
            </contact>
          </surface>
        </collision>
        <visual name='Wall_43_Visual'>
          <pose>0 0 1.25 0 -0 0</pose>
          <geometry>
            <box>
              <size>30 0.15 2.5</size>
            </box>
          </geometry>
          <material>
            <script>
              <uri>file://media/materials/scripts/gazebo.material</uri>
              <name>Gazebo/CeilingTiled</name>
            </script>
            <ambient>1 1 1 1</ambient>
          </material>
        </visual>
        <pose>-20.4925 13.0738 0 0 -0 0</pose>
        <velocity_decay>
          <linear>0</linear>
          <angular>0</angular>
        </velocity_decay>
        <self_collide>0</self_collide>
        <kinematic>0</kinematic>
        <gravity>1</gravity>
      </link>
      <link name='Wall_44'>
        <collision name='Wall_44_Collision'>
          <geometry>
            <box>
              <size>8.75 0.15 2.5</size>
            </box>
          </geometry>
          <pose>0 0 1.25 0 -0 0</pose>
          <max_contacts>10</max_contacts>
          <surface>
            <bounce/>
            <friction>
              <ode/>
            </friction>
            <contact>
              <ode/>
            </contact>
          </surface>
        </collision>
        <visual name='Wall_44_Visual'>
          <pose>0 0 1.25 0 -0 0</pose>
          <geometry>
            <box>
              <size>8.75 0.15 2.5</size>
            </box>
          </geometry>
          <material>
            <script>
              <uri>file://media/materials/scripts/gazebo.material</uri>
              <name>Gazebo/CeilingTiled</name>
            </script>
            <ambient>1 1 1 1</ambient>
          </material>
        </visual>
        <pose>-5.56745 8.77384 0 0 0 -1.5708</pose>
        <velocity_decay>
          <linear>0</linear>
          <angular>0</angular>
        </velocity_decay>
        <self_collide>0</self_collide>
        <kinematic>0</kinematic>
        <gravity>1</gravity>
      </link>
      <link name='Wall_45'>
        <collision name='Wall_45_Collision'>
          <geometry>
            <box>
              <size>13.75 0.15 2.5</size>
            </box>
          </geometry>
          <pose>0 0 1.25 0 -0 0</pose>
          <max_contacts>10</max_contacts>
          <surface>
            <bounce/>
            <friction>
              <ode/>
            </friction>
            <contact>
              <ode/>
            </contact>
          </surface>
        </collision>
        <visual name='Wall_45_Visual'>
          <pose>0 0 1.25 0 -0 0</pose>
          <geometry>
            <box>
              <size>13.75 0.15 2.5</size>
            </box>
          </geometry>
          <material>
            <script>
              <uri>file://media/materials/scripts/gazebo.material</uri>
              <name>Gazebo/CeilingTiled</name>
            </script>
            <ambient>1 1 1 1</ambient>
          </material>
        </visual>
        <pose>1.23255 4.47384 0 0 -0 0</pose>
        <velocity_decay>
          <linear>0</linear>
          <angular>0</angular>
        </velocity_decay>
        <self_collide>0</self_collide>
        <kinematic>0</kinematic>
        <gravity>1</gravity>
      </link>
      <link name='Wall_46'>
        <collision name='Wall_46_Collision'>
          <geometry>
            <box>
              <size>2.25 0.15 2.5</size>
            </box>
          </geometry>
          <pose>0 0 1.25 0 -0 0</pose>
          <max_contacts>10</max_contacts>
          <surface>
            <bounce/>
            <friction>
              <ode/>
            </friction>
            <contact>
              <ode/>
            </contact>
          </surface>
        </collision>
        <visual name='Wall_46_Visual'>
          <pose>0 0 1.25 0 -0 0</pose>
          <geometry>
            <box>
              <size>2.25 0.15 2.5</size>
            </box>
          </geometry>
          <material>
            <script>
              <uri>file://media/materials/scripts/gazebo.material</uri>
              <name>Gazebo/CeilingTiled</name>
            </script>
            <ambient>1 1 1 1</ambient>
          </material>
        </visual>
        <pose>8.03255 3.42384 0 0 0 -1.5708</pose>
        <velocity_decay>
          <linear>0</linear>
          <angular>0</angular>
        </velocity_decay>
        <self_collide>0</self_collide>
        <kinematic>0</kinematic>
        <gravity>1</gravity>
      </link>
      <link name='Wall_47'>
        <collision name='Wall_47_Collision'>
          <geometry>
            <box>
              <size>15.8243 0.15 2.5</size>
            </box>
          </geometry>
          <pose>0 0 1.25 0 -0 0</pose>
          <max_contacts>10</max_contacts>
          <surface>
            <bounce/>
            <friction>
              <ode/>
            </friction>
            <contact>
              <ode/>
            </contact>
          </surface>
        </collision>
        <visual name='Wall_47_Visual'>
          <pose>0 0 1.25 0 -0 0</pose>
          <geometry>
            <box>
              <size>15.8243 0.15 2.5</size>
            </box>
          </geometry>
          <material>
            <script>
              <uri>file://media/materials/scripts/gazebo.material</uri>
              <name>Gazebo/CeilingTiled</name>
            </script>
            <ambient>1 1 1 1</ambient>
          </material>
        </visual>
        <pose>2.89068 -3.54071 0 0 0 -2.28642</pose>
        <velocity_decay>
          <linear>0</linear>
          <angular>0</angular>
        </velocity_decay>
        <self_collide>0</self_collide>
        <kinematic>0</kinematic>
        <gravity>1</gravity>
      </link>
      <link name='Wall_5'>
        <collision name='Wall_5_Collision'>
          <geometry>
            <box>
              <size>41.5 0.15 2.5</size>
            </box>
          </geometry>
          <pose>0 0 1.25 0 -0 0</pose>
          <max_contacts>10</max_contacts>
          <surface>
            <bounce/>
            <friction>
              <ode/>
            </friction>
            <contact>
              <ode/>
            </contact>
          </surface>
        </collision>
        <visual name='Wall_5_Visual'>
          <pose>0 0 1.25 0 -0 0</pose>
          <geometry>
            <box>
              <size>41.5 0.15 2.5</size>
            </box>
          </geometry>
          <material>
            <script>
              <uri>file://media/materials/scripts/gazebo.material</uri>
              <name>Gazebo/CeilingTiled</name>
            </script>
            <ambient>1 1 1 1</ambient>
          </material>
        </visual>
        <pose>-40.2 2.40609 0 0 -0 1.5708</pose>
        <velocity_decay>
          <linear>0</linear>
          <angular>0</angular>
        </velocity_decay>
        <self_collide>0</self_collide>
        <kinematic>0</kinematic>
        <gravity>1</gravity>
      </link>
      <link name='Wall_50'>
        <collision name='Wall_50_Collision'>
          <geometry>
            <box>
              <size>1 0.15 2.5</size>
            </box>
          </geometry>
          <pose>0 0 1.25 0 -0 0</pose>
          <max_contacts>10</max_contacts>
          <surface>
            <bounce/>
            <friction>
              <ode/>
            </friction>
            <contact>
              <ode/>
            </contact>
          </surface>
        </collision>
        <visual name='Wall_50_Visual'>
          <pose>0 0 1.25 0 -0 0</pose>
          <geometry>
            <box>
              <size>1 0.15 2.5</size>
            </box>
          </geometry>
          <material>
            <script>
              <uri>file://media/materials/scripts/gazebo.material</uri>
              <name>Gazebo/Grey</name>
            </script>
            <ambient>1 1 1 1</ambient>
          </material>
        </visual>
        <pose>-2.6617 -9.34526 0 0 -0 2.87979</pose>
        <velocity_decay>
          <linear>0</linear>
          <angular>0</angular>
        </velocity_decay>
        <self_collide>0</self_collide>
        <kinematic>0</kinematic>
        <gravity>1</gravity>
      </link>
      <link name='Wall_51'>
        <collision name='Wall_51_Collision'>
          <geometry>
            <box>
              <size>1.75 0.15 2.5</size>
            </box>
          </geometry>
          <pose>0 0 1.25 0 -0 0</pose>
          <max_contacts>10</max_contacts>
          <surface>
            <bounce/>
            <friction>
              <ode/>
            </friction>
            <contact>
              <ode/>
            </contact>
          </surface>
        </collision>
        <visual name='Wall_51_Visual'>
          <pose>0 0 1.25 0 -0 0</pose>
          <geometry>
            <box>
              <size>1.75 0.15 2.5</size>
            </box>
          </geometry>
          <material>
            <script>
              <uri>file://media/materials/scripts/gazebo.material</uri>
              <name>Gazebo/CeilingTiled</name>
            </script>
            <ambient>1 1 1 1</ambient>
          </material>
        </visual>
        <pose>-3.47221 -9.92808 0 0 0 -2.0944</pose>
        <velocity_decay>
          <linear>0</linear>
          <angular>0</angular>
        </velocity_decay>
        <self_collide>0</self_collide>
        <kinematic>0</kinematic>
        <gravity>1</gravity>
      </link>
      <link name='Wall_52'>
        <collision name='Wall_52_Collision'>
          <geometry>
            <box>
              <size>1.5 0.15 2.5</size>
            </box>
          </geometry>
          <pose>0 0 1.25 0 -0 0</pose>
          <max_contacts>10</max_contacts>
          <surface>
            <bounce/>
            <friction>
              <ode/>
            </friction>
            <contact>
              <ode/>
            </contact>
          </surface>
        </collision>
        <visual name='Wall_52_Visual'>
          <pose>0 0 1.25 0 -0 0</pose>
          <geometry>
            <box>
              <size>1.5 0.15 2.5</size>
            </box>
          </geometry>
          <material>
            <script>
              <uri>file://media/materials/scripts/gazebo.material</uri>
              <name>Gazebo/CeilingTiled</name>
            </script>
            <ambient>1 1 1 1</ambient>
          </material>
        </visual>
        <pose>-3.39492 -11.0982 0 0 0 -0.785398</pose>
        <velocity_decay>
          <linear>0</linear>
          <angular>0</angular>
        </velocity_decay>
        <self_collide>0</self_collide>
        <kinematic>0</kinematic>
        <gravity>1</gravity>
      </link>
      <link name='Wall_53'>
        <collision name='Wall_53_Collision'>
          <geometry>
            <box>
              <size>0.75 0.15 2.5</size>
            </box>
          </geometry>
          <pose>0 0 1.25 0 -0 0</pose>
          <max_contacts>10</max_contacts>
          <surface>
            <bounce/>
            <friction>
              <ode/>
            </friction>
            <contact>
              <ode/>
            </contact>
          </surface>
        </collision>
        <visual name='Wall_53_Visual'>
          <pose>0 0 1.25 0 -0 0</pose>
          <geometry>
            <box>
              <size>0.75 0.15 2.5</size>
            </box>
          </geometry>
          <material>
            <script>
              <uri>file://media/materials/scripts/gazebo.material</uri>
              <name>Gazebo/CeilingTiled</name>
            </script>
            <ambient>1 1 1 1</ambient>
          </material>
        </visual>
        <pose>-3.12975 -11.7876 0 0 0 -2.35619</pose>
        <velocity_decay>
          <linear>0</linear>
          <angular>0</angular>
        </velocity_decay>
        <self_collide>0</self_collide>
        <kinematic>0</kinematic>
        <gravity>1</gravity>
      </link>
      <link name='Wall_54'>
        <collision name='Wall_54_Collision'>
          <geometry>
            <box>
              <size>0.75 0.15 2.5</size>
            </box>
          </geometry>
          <pose>0 0 1.25 0 -0 0</pose>
          <max_contacts>10</max_contacts>
          <surface>
            <bounce/>
            <friction>
              <ode/>
            </friction>
            <contact>
              <ode/>
            </contact>
          </surface>
        </collision>
        <visual name='Wall_54_Visual'>
          <pose>0 0 1.25 0 -0 0</pose>
          <geometry>
            <box>
              <size>0.75 0.15 2.5</size>
            </box>
          </geometry>
          <material>
            <script>
              <uri>file://media/materials/scripts/gazebo.material</uri>
              <name>Gazebo/Grey</name>
            </script>
            <ambient>1 1 1 1</ambient>
          </material>
        </visual>
        <pose>-3.64188 -11.9998 0 0 -0 3.14159</pose>
        <velocity_decay>
          <linear>0</linear>
          <angular>0</angular>
        </velocity_decay>
        <self_collide>0</self_collide>
        <kinematic>0</kinematic>
        <gravity>1</gravity>
      </link>
      <link name='Wall_55'>
        <collision name='Wall_55_Collision'>
          <geometry>
            <box>
              <size>7.13355 0.15 2.5</size>
            </box>
          </geometry>
          <pose>0 0 1.25 0 -0 0</pose>
          <max_contacts>10</max_contacts>
          <surface>
            <bounce/>
            <friction>
              <ode/>
            </friction>
            <contact>
              <ode/>
            </contact>
          </surface>
        </collision>
        <visual name='Wall_55_Visual'>
          <pose>0 0 1.25 0 -0 0</pose>
          <geometry>
            <box>
              <size>7.13355 0.15 2.5</size>
            </box>
          </geometry>
          <material>
            <script>
              <uri>file://media/materials/scripts/gazebo.material</uri>
              <name>Gazebo/CeilingTiled</name>
            </script>
            <ambient>1 1 1 1</ambient>
          </material>
        </visual>
        <pose>-5.21192 -15.2524 0 0 0 -1.94306</pose>
        <velocity_decay>
          <linear>0</linear>
          <angular>0</angular>
        </velocity_decay>
        <self_collide>0</self_collide>
        <kinematic>0</kinematic>
        <gravity>1</gravity>
      </link>
      <link name='Wall_57'>
        <collision name='Wall_57_Collision'>
          <geometry>
            <box>
              <size>29 0.15 2.5</size>
            </box>
          </geometry>
          <pose>0 0 1.25 0 -0 0</pose>
          <max_contacts>10</max_contacts>
          <surface>
            <bounce/>
            <friction>
              <ode/>
            </friction>
            <contact>
              <ode/>
            </contact>
          </surface>
        </collision>
        <visual name='Wall_57_Visual'>
          <pose>0 0 1.25 0 -0 0</pose>
          <geometry>
            <box>
              <size>29 0.15 2.5</size>
            </box>
          </geometry>
          <material>
            <script>
              <uri>file://media/materials/scripts/gazebo.material</uri>
              <name>Gazebo/CeilingTiled</name>
            </script>
            <ambient>1 1 1 1</ambient>
          </material>
        </visual>
        <pose>-20.9925 -18.5262 0 0 -0 0</pose>
        <velocity_decay>
          <linear>0</linear>
          <angular>0</angular>
        </velocity_decay>
        <self_collide>0</self_collide>
        <kinematic>0</kinematic>
        <gravity>1</gravity>
      </link>
      <link name='Wall_9'>
        <collision name='Wall_9_Collision'>
          <geometry>
            <box>
              <size>7.75 0.15 2.5</size>
            </box>
          </geometry>
          <pose>0 0 1.25 0 -0 0</pose>
          <max_contacts>10</max_contacts>
          <surface>
            <bounce/>
            <friction>
              <ode/>
            </friction>
            <contact>
              <ode/>
            </contact>
          </surface>
        </collision>
        <visual name='Wall_9_Visual'>
          <pose>0 0 1.25 0 -0 0</pose>
          <geometry>
            <box>
              <size>7.75 0.15 2.5</size>
            </box>
          </geometry>
          <material>
            <script>
              <uri>file://media/materials/scripts/gazebo.material</uri>
              <name>Gazebo/CeilingTiled</name>
            </script>
            <ambient>1 1 1 1</ambient>
          </material>
        </visual>
        <pose>-35.4657 19.3427 0 0 0 -1.5708</pose>
        <velocity_decay>
          <linear>0</linear>
          <angular>0</angular>
        </velocity_decay>
        <self_collide>0</self_collide>
        <kinematic>0</kinematic>
        <gravity>1</gravity>
      </link>
      <static>1</static>
    </model>
    <physics type='ode'>
      <max_step_size>0.001</max_step_size>
      <real_time_factor>1</real_time_factor>
      <real_time_update_rate>1000</real_time_update_rate>
      <gravity>0 0 -9.8</gravity>
    </physics>
    <scene>
      <ambient>0.4 0.4 0.4 1</ambient>
      <background>0.7 0.7 0.7 1</background>
      <shadows>1</shadows>
    </scene>
    <spherical_coordinates>
      <surface_model>EARTH_WGS84</surface_model>
      <latitude_deg>0</latitude_deg>
      <longitude_deg>0</longitude_deg>
      <elevation>0</elevation>
      <heading_deg>0</heading_deg>
    </spherical_coordinates>
    <model name='racecar'>
      <link name='chassis'>
        <pose>0 0 0 0 -0 0</pose>
        <inertial>
          <pose>0.1477 0 0 0 -0 0</pose>
          <mass>4</mass>
          <inertia>
            <ixx>0.010609</ixx>
            <ixy>0</ixy>
            <ixz>0</ixz>
            <iyy>0.050409</iyy>
            <iyz>0</iyz>
            <izz>0.05865</izz>
          </inertia>
        </inertial>
        <visual name='chassis_visual'>
          <pose>0 0 0 0 -0 0</pose>
          <geometry>
            <mesh>
              <scale>1 1 1</scale>
              <uri>/home/racecar/team-ws/src/racecar_simulator/racecar_description/meshes/chassis.STL</uri>
            </mesh>
          </geometry>
          <material>
            <script>
              <name>Gazebo/Blue</name>
              <uri>__default__</uri>
            </script>
          </material>
        </visual>
        <gravity>1</gravity>
        <velocity_decay>
          <linear>0</linear>
          <angular>0</angular>
        </velocity_decay>
        <self_collide>0</self_collide>
        <kinematic>0</kinematic>
      </link>
      <link name='camera_link'>
        <pose>0.35 0 0.05 0 -0 0</pose>
        <inertial>
          <pose>0 0 0 0 -0 0</pose>
          <mass>1e-05</mass>
          <inertia>
            <ixx>1e-06</ixx>
            <ixy>0</ixy>
            <ixz>0</ixz>
            <iyy>1e-06</iyy>
            <iyz>0</iyz>
            <izz>1e-06</izz>
          </inertia>
        </inertial>
        <collision name='camera_link_collision'>
          <pose>0 0 0 0 -0 0</pose>
          <geometry>
            <box>
              <size>0.05 0.05 0.05</size>
            </box>
          </geometry>
          <surface>
            <contact>
              <ode/>
            </contact>
            <friction>
              <ode/>
            </friction>
            <bounce/>
          </surface>
          <max_contacts>10</max_contacts>
        </collision>
        <visual name='camera_link_visual'>
          <pose>0 0 0 0 -0 0</pose>
          <geometry>
            <box>
              <size>0.05 0.05 0.05</size>
            </box>
          </geometry>
        </visual>
        <gravity>1</gravity>
        <velocity_decay>
          <linear>0</linear>
          <angular>0</angular>
        </velocity_decay>
        <self_collide>0</self_collide>
        <sensor name='camera1' type='camera'>
          <update_rate>30</update_rate>
          <camera name='head'>
            <horizontal_fov>0.870922</horizontal_fov>
            <image>
              <width>640</width>
              <height>480</height>
              <format>B8G8R8</format>
            </image>
            <clip>
              <near>0.02</near>
              <far>300</far>
            </clip>
            <noise>
              <type>gaussian</type>
              <mean>0</mean>
              <stddev>0.007</stddev>
            </noise>
          </camera>
          <plugin name='camera_controller' filename='libgazebo_ros_camera.so'>
            <alwaysOn>true</alwaysOn>
            <updateRate>30.0</updateRate>
            <cameraName>/camera/zed</cameraName>
            <imageTopicName>rgb/image_rect_color</imageTopicName>
            <cameraInfoTopicName>camera_info</cameraInfoTopicName>
            <frameName>camera_link</frameName>
            <hackBaseline>0.07</hackBaseline>
            <distortionK1>0.0</distortionK1>
            <distortionK2>0.0</distortionK2>
            <distortionK3>0.0</distortionK3>
            <distortionT1>0.0</distortionT1>
            <distortionT2>0.0</distortionT2>
            <robotNamespace>/</robotNamespace>
          </plugin>
        </sensor>
        <kinematic>0</kinematic>
      </link>
      <joint name='camera_joint' type='revolute'>
        <child>camera_link</child>
        <parent>chassis</parent>
        <axis>
          <xyz>0 0 1</xyz>
          <limit>
            <lower>0</lower>
            <upper>0</upper>
            <effort>0</effort>
            <velocity>0</velocity>
          </limit>
          <dynamics/>
        </axis>
      </joint>
      <link name='hokuyo_link'>
        <pose>0.325 0 0.065 0 -0 0</pose>
        <inertial>
          <pose>0 0 0 0 -0 0</pose>
          <mass>0.13</mass>
          <inertia>
            <ixx>4e-06</ixx>
            <ixy>0</ixy>
            <ixz>0</ixz>
            <iyy>4e-06</iyy>
            <iyz>0</iyz>
            <izz>4e-06</izz>
          </inertia>
        </inertial>
        <collision name='hokuyo_link_collision'>
          <pose>0 0 0 0 -0 0</pose>
          <geometry>
            <box>
              <size>0.1 0.1 0.1</size>
            </box>
          </geometry>
          <surface>
            <contact>
              <ode/>
            </contact>
            <friction>
              <ode/>
            </friction>
            <bounce/>
          </surface>
          <max_contacts>10</max_contacts>
        </collision>
        <visual name='hokuyo_link_visual'>
          <pose>0 0 0 0 -0 0</pose>
          <geometry>
            <mesh>
              <scale>1 1 1</scale>
              <uri>/home/racecar/team-ws/src/racecar_simulator/racecar_description/meshes/hokuyo.dae</uri>
            </mesh>
          </geometry>
          <material>
            <script>
              <name>Gazebo/Grey</name>
              <uri>__default__</uri>
            </script>
          </material>
        </visual>
        <gravity>1</gravity>
        <velocity_decay>
          <linear>0</linear>
          <angular>0</angular>
        </velocity_decay>
        <self_collide>0</self_collide>
        <sensor name='hokuyo_sensor' type='ray'>
          <pose>0 0 0.0124 0 -0 0</pose>
          <visualize>1</visualize>
          <update_rate>40</update_rate>
          <ray>
            <scan>
              <horizontal>
                <samples>1080</samples>
                <resolution>1</resolution>
                <min_angle>-2.35619</min_angle>
                <max_angle>2.35619</max_angle>
              </horizontal>
            </scan>
            <range>
              <min>0.1</min>
              <max>10</max>
              <resolution>0.01</resolution>
            </range>
            <noise>
              <mean>0</mean>
              <stddev>0.01</stddev>
              <type>gaussian</type>
            </noise>
          </ray>
          <plugin name='gazebo_ros_hokuyo_controller' filename='libgazebo_ros_laser.so'>
            <topicName>/racecar/laser/scan</topicName>
            <frameName>hokuyo_link</frameName>
            <robotNamespace>/</robotNamespace>
          </plugin>
        </sensor>
        <kinematic>0</kinematic>
      </link>
      <joint name='hokuyo_joint' type='revolute'>
        <child>hokuyo_link</child>
        <parent>chassis</parent>
        <axis>
          <xyz>0 0 1</xyz>
          <limit>
            <lower>0</lower>
            <upper>0</upper>
            <effort>0</effort>
            <velocity>0</velocity>
          </limit>
          <dynamics/>
        </axis>
      </joint>
      <link name='left_rear_wheel'>
        <pose>0 0.1 0 1.5708 -0 0</pose>
        <inertial>
          <pose>0 0 -0.0225 0 -0 0</pose>
          <mass>0.34055</mass>
          <inertia>
            <ixx>0.00026046</ixx>
            <ixy>0</ixy>
            <ixz>0</ixz>
            <iyy>0.00026046</iyy>
            <iyz>0</iyz>
            <izz>0.00041226</izz>
          </inertia>
        </inertial>
        <collision name='left_rear_wheel_collision'>
          <pose>0 0 -0.0225 0 -0 0</pose>
          <geometry>
            <cylinder>
              <length>0.045</length>
              <radius>0.05</radius>
            </cylinder>
          </geometry>
          <surface>
            <contact>
              <ode>
                <kp>1e+07</kp>
                <kd>1</kd>
              </ode>
            </contact>
            <friction>
              <ode>
                <mu>1000</mu>
                <mu2>1000</mu2>
                <fdir1>1 0 0</fdir1>
              </ode>
            </friction>
            <bounce/>
          </surface>
          <max_contacts>10</max_contacts>
        </collision>
        <visual name='left_rear_wheel_visual'>
          <pose>0 0 0 0 -0 0</pose>
          <geometry>
            <mesh>
              <scale>1 1 1</scale>
              <uri>/home/racecar/team-ws/src/racecar_simulator/racecar_description/meshes/left_rear_wheel.STL</uri>
            </mesh>
          </geometry>
          <material>
            <script>
              <name>Gazebo/Black</name>
              <uri>__default__</uri>
            </script>
          </material>
        </visual>
        <gravity>1</gravity>
        <velocity_decay>
          <linear>0</linear>
          <angular>0</angular>
        </velocity_decay>
        <self_collide>0</self_collide>
        <kinematic>0</kinematic>
      </link>
      <joint name='left_rear_wheel_joint' type='revolute'>
        <child>left_rear_wheel</child>
        <parent>chassis</parent>
        <axis>
          <xyz>0 -1 -4e-06</xyz>
          <limit>
            <lower>-1e+16</lower>
            <upper>1e+16</upper>
          </limit>
          <dynamics/>
        </axis>
      </joint>
      <link name='left_steering_hinge'>
        <pose>0.325 0.1 0 3.14159 1.57079 3.14159</pose>
        <inertial>
          <pose>0 0 0 0 -0 0</pose>
          <mass>0.1</mass>
          <inertia>
            <ixx>4e-06</ixx>
            <ixy>0</ixy>
            <ixz>0</ixz>
            <iyy>4e-06</iyy>
            <iyz>0</iyz>
            <izz>4e-06</izz>
          </inertia>
        </inertial>
        <visual name='left_steering_hinge_visual'>
          <pose>0 0 0 0 -0 0</pose>
          <geometry>
            <mesh>
              <scale>1 1 1</scale>
              <uri>/home/racecar/team-ws/src/racecar_simulator/racecar_description/meshes/left_steering_hinge.STL</uri>
            </mesh>
          </geometry>
        </visual>
        <velocity_decay>
          <linear>0</linear>
          <angular>0</angular>
        </velocity_decay>
        <self_collide>0</self_collide>
        <kinematic>0</kinematic>
        <gravity>1</gravity>
      </link>
      <joint name='left_steering_hinge_joint' type='revolute'>
        <child>left_steering_hinge</child>
        <parent>chassis</parent>
        <axis>
          <xyz>4e-06 0 1</xyz>
          <limit>
            <lower>-1</lower>
            <upper>1</upper>
            <effort>10</effort>
            <velocity>100</velocity>
          </limit>
          <dynamics/>
        </axis>
      </joint>
      <link name='left_front_wheel'>
        <pose>0.325 0.1 0 -1.57079 1.57079 3.14159</pose>
        <inertial>
          <pose>0 0 -0.0225 0 -0 0</pose>
          <mass>0.34055</mass>
          <inertia>
            <ixx>0.00026046</ixx>
            <ixy>0</ixy>
            <ixz>0</ixz>
            <iyy>0.00026046</iyy>
            <iyz>0</iyz>
            <izz>0.00041226</izz>
          </inertia>
        </inertial>
        <collision name='left_front_wheel_collision'>
          <pose>0 0 -0.0225 0 -0 0</pose>
          <geometry>
            <cylinder>
              <length>0.045</length>
              <radius>0.05</radius>
            </cylinder>
          </geometry>
          <surface>
            <contact>
              <ode>
                <kp>1e+07</kp>
                <kd>1</kd>
              </ode>
            </contact>
            <friction>
              <ode>
                <mu>1000</mu>
                <mu2>1000</mu2>
                <fdir1>1 0 0</fdir1>
              </ode>
            </friction>
            <bounce/>
          </surface>
          <max_contacts>10</max_contacts>
        </collision>
        <visual name='left_front_wheel_visual'>
          <pose>0 0 0 0 -0 0</pose>
          <geometry>
            <mesh>
              <scale>1 1 1</scale>
              <uri>/home/racecar/team-ws/src/racecar_simulator/racecar_description/meshes/left_front_wheel.STL</uri>
            </mesh>
          </geometry>
          <material>
            <script>
              <name>Gazebo/Black</name>
              <uri>__default__</uri>
            </script>
          </material>
        </visual>
        <gravity>1</gravity>
        <velocity_decay>
          <linear>0</linear>
          <angular>0</angular>
        </velocity_decay>
        <self_collide>0</self_collide>
        <kinematic>0</kinematic>
      </link>
      <joint name='left_front_wheel_joint' type='revolute'>
        <child>left_front_wheel</child>
        <parent>left_steering_hinge</parent>
        <axis>
          <xyz>4e-06 1 -0</xyz>
          <limit>
            <lower>-1e+16</lower>
            <upper>1e+16</upper>
          </limit>
          <dynamics/>
        </axis>
      </joint>
      <link name='right_rear_wheel'>
        <pose>0 -0.1 0 1.5708 -0 0</pose>
        <inertial>
          <pose>0 0 0.0225 0 -0 0</pose>
          <mass>0.34055</mass>
          <inertia>
            <ixx>0.00026046</ixx>
            <ixy>0</ixy>
            <ixz>0</ixz>
            <iyy>0.00026046</iyy>
            <iyz>0</iyz>
            <izz>0.00041226</izz>
          </inertia>
        </inertial>
        <collision name='right_rear_wheel_collision'>
          <pose>0 0 0.0225 0 -0 0</pose>
          <geometry>
            <cylinder>
              <length>0.045</length>
              <radius>0.05</radius>
            </cylinder>
          </geometry>
          <surface>
            <contact>
              <ode>
                <kp>1e+07</kp>
                <kd>1</kd>
              </ode>
            </contact>
            <friction>
              <ode>
                <mu>1000</mu>
                <mu2>1000</mu2>
                <fdir1>1 0 0</fdir1>
              </ode>
            </friction>
            <bounce/>
          </surface>
          <max_contacts>10</max_contacts>
        </collision>
        <visual name='right_rear_wheel_visual'>
          <pose>0 0 0 0 -0 0</pose>
          <geometry>
            <mesh>
              <scale>1 1 1</scale>
              <uri>/home/racecar/team-ws/src/racecar_simulator/racecar_description/meshes/right_rear_wheel.STL</uri>
            </mesh>
          </geometry>
          <material>
            <script>
              <name>Gazebo/Black</name>
              <uri>__default__</uri>
            </script>
          </material>
        </visual>
        <gravity>1</gravity>
        <velocity_decay>
          <linear>0</linear>
          <angular>0</angular>
        </velocity_decay>
        <self_collide>0</self_collide>
        <kinematic>0</kinematic>
      </link>
      <joint name='right_rear_wheel_joint' type='revolute'>
        <child>right_rear_wheel</child>
        <parent>chassis</parent>
        <axis>
          <xyz>0 -1 -4e-06</xyz>
          <limit>
            <lower>-1e+16</lower>
            <upper>1e+16</upper>
          </limit>
          <dynamics/>
        </axis>
      </joint>
      <link name='right_steering_hinge'>
        <pose>0.325 -0.1 0 3.14159 1.57079 3.14159</pose>
        <inertial>
          <pose>0 0 0 0 -0 0</pose>
          <mass>0.1</mass>
          <inertia>
            <ixx>4e-06</ixx>
            <ixy>0</ixy>
            <ixz>0</ixz>
            <iyy>4e-06</iyy>
            <iyz>0</iyz>
            <izz>4e-06</izz>
          </inertia>
        </inertial>
        <visual name='right_steering_hinge_visual'>
          <pose>0 0 0 0 -0 0</pose>
          <geometry>
            <mesh>
              <scale>1 1 1</scale>
              <uri>/home/racecar/team-ws/src/racecar_simulator/racecar_description/meshes/right_steering_hinge.STL</uri>
            </mesh>
          </geometry>
        </visual>
        <velocity_decay>
          <linear>0</linear>
          <angular>0</angular>
        </velocity_decay>
        <self_collide>0</self_collide>
        <kinematic>0</kinematic>
        <gravity>1</gravity>
      </link>
      <joint name='right_steering_hinge_joint' type='revolute'>
        <child>right_steering_hinge</child>
        <parent>chassis</parent>
        <axis>
          <xyz>4e-06 0 1</xyz>
          <limit>
            <lower>-1e+16</lower>
            <upper>1e+16</upper>
          </limit>
          <dynamics/>
        </axis>
      </joint>
      <link name='right_front_wheel'>
        <pose>0.325 -0.1 0 -1.57079 1.57079 3.14159</pose>
        <inertial>
          <pose>0 0 0.0225 0 -0 0</pose>
          <mass>0.34055</mass>
          <inertia>
            <ixx>0.00026046</ixx>
            <ixy>0</ixy>
            <ixz>0</ixz>
            <iyy>0.00026046</iyy>
            <iyz>0</iyz>
            <izz>0.00041226</izz>
          </inertia>
        </inertial>
        <collision name='right_front_wheel_collision'>
          <pose>0 0 0.0225 0 -0 0</pose>
          <geometry>
            <cylinder>
              <length>0.045</length>
              <radius>0.05</radius>
            </cylinder>
          </geometry>
          <surface>
            <contact>
              <ode>
                <kp>1e+07</kp>
                <kd>1</kd>
              </ode>
            </contact>
            <friction>
              <ode>
                <mu>1000</mu>
                <mu2>1000</mu2>
                <fdir1>1 0 0</fdir1>
              </ode>
            </friction>
            <bounce/>
          </surface>
          <max_contacts>10</max_contacts>
        </collision>
        <visual name='right_front_wheel_visual'>
          <pose>0 0 0 0 -0 0</pose>
          <geometry>
            <mesh>
              <scale>1 1 1</scale>
              <uri>/home/racecar/team-ws/src/racecar_simulator/racecar_description/meshes/right_front_wheel.STL</uri>
            </mesh>
          </geometry>
          <material>
            <script>
              <name>Gazebo/Black</name>
              <uri>__default__</uri>
            </script>
          </material>
        </visual>
        <gravity>1</gravity>
        <velocity_decay>
          <linear>0</linear>
          <angular>0</angular>
        </velocity_decay>
        <self_collide>0</self_collide>
        <kinematic>0</kinematic>
      </link>
      <joint name='right_front_wheel_joint' type='revolute'>
        <child>right_front_wheel</child>
        <parent>right_steering_hinge</parent>
        <axis>
          <xyz>4e-06 1 -0</xyz>
          <limit>
            <lower>-1e+16</lower>
            <upper>1e+16</upper>
          </limit>
          <dynamics/>
        </axis>
      </joint>
      <static>0</static>
      <plugin name='gazebo_ros_control' filename='libgazebo_ros_control.so'>
        <robotNamespace>/racecar</robotNamespace>
        <robotSimType>gazebo_ros_control/DefaultRobotHWSim</robotSimType>
      </plugin>
      <pose>0 0 0.05 0 -0 0</pose>
    </model>
    <model name='Construction Cone'>
      <link name='link'>
        <collision name='collision'>
          <geometry>
            <mesh>
              <scale>10 10 10</scale>
              <uri>model://construction_cone/meshes/construction_cone.dae</uri>
            </mesh>
          </geometry>
          <max_contacts>10</max_contacts>
          <surface>
            <bounce/>
            <friction>
              <ode/>
            </friction>
            <contact>
              <ode/>
            </contact>
          </surface>
        </collision>
        <visual name='visual'>
          <geometry>
            <mesh>
              <scale>10 10 10</scale>
              <uri>model://construction_cone/meshes/construction_cone.dae</uri>
            </mesh>
          </geometry>
        </visual>
        <velocity_decay>
          <linear>0</linear>
          <angular>0</angular>
        </velocity_decay>
        <self_collide>0</self_collide>
        <inertial>
          <inertia>
            <ixx>1</ixx>
            <ixy>0</ixy>
            <ixz>0</ixz>
            <iyy>1</iyy>
            <iyz>0</iyz>
            <izz>1</izz>
          </inertia>
          <mass>1</mass>
        </inertial>
        <kinematic>0</kinematic>
        <gravity>1</gravity>
      </link>
      <pose>1.56453 0 0 0 -0 0</pose>
      <static>0</static>
    </model>
    <state world_name='racecar_tunnel'>
      <sim_time>235 317000000</sim_time>
      <real_time>609 67890580</real_time>
      <wall_time>1457547434 820574044</wall_time>
      <model name='Construction Cone'>
        <pose>1.56453 0 -7e-06 -1e-06 -1e-06 1.25527e-28</pose>
        <link name='link'>
          <pose>1.56453 0 -7e-06 -1e-06 -1e-06 1.25527e-28</pose>
          <velocity>0 0 0 0 -0 0</velocity>
          <acceleration>-0.000111 2e-06 7.20005 -2.31384 -2e-06 1e-06</acceleration>
          <wrench>-0.000111 2e-06 7.20005 0 -0 0</wrench>
        </link>
      </model>
      <model name='MIT_Tunnel'>
        <pose>6 20 0 0 -0 0</pose>
        <link name='Wall_10'>
          <pose>-13.1952 35.5558 0 0 0 -0.001042</pose>
          <velocity>0 0 0 0 -0 0</velocity>
          <acceleration>0 0 0 0 -0 0</acceleration>
          <wrench>0 0 0 0 -0 0</wrench>
        </link>
        <link name='Wall_12'>
          <pose>3.07517 31.3639 0 0 0 -1.5708</pose>
          <velocity>0 0 0 0 -0 0</velocity>
          <acceleration>0 0 0 0 -0 0</acceleration>
          <wrench>0 0 0 0 -0 0</wrench>
        </link>
        <link name='Wall_15'>
          <pose>12.3752 27.1889 0 0 -0 0</pose>
          <velocity>0 0 0 0 -0 0</velocity>
          <acceleration>0 0 0 0 -0 0</acceleration>
          <wrench>0 0 0 0 -0 0</wrench>
        </link>
        <link name='Wall_17'>
          <pose>21.0799 24.9673 0 0 0 -1.8326</pose>
          <velocity>0 0 0 0 -0 0</velocity>
          <acceleration>0 0 0 0 -0 0</acceleration>
          <wrench>0 0 0 0 -0 0</wrench>
        </link>
        <link name='Wall_18'>
          <pose>19.1846 22.7456 0 0 -0 3.14159</pose>
          <velocity>0 0 0 0 -0 0</velocity>
          <acceleration>0 0 0 0 -0 0</acceleration>
          <wrench>0 0 0 0 -0 0</wrench>
        </link>
        <link name='Wall_19'>
          <pose>16.9654 21.8264 0 0 0 -2.35619</pose>
          <velocity>0 0 0 0 -0 0</velocity>
          <acceleration>0 0 0 0 -0 0</acceleration>
          <wrench>0 0 0 0 -0 0</wrench>
        </link>
        <link name='Wall_2'>
          <pose>-46.25 1.7311 0 0 -0 0</pose>
          <velocity>0 0 0 0 -0 0</velocity>
          <acceleration>0 0 0 0 -0 0</acceleration>
          <wrench>0 0 0 0 -0 0</wrench>
        </link>
        <link name='Wall_20'>
          <pose>16.0461 19.8572 0 0 0 -1.5708</pose>
          <velocity>0 0 0 0 -0 0</velocity>
          <acceleration>0 0 0 0 -0 0</acceleration>
          <wrench>0 0 0 0 -0 0</wrench>
        </link>
        <link name='Wall_22'>
          <pose>14.5385 16.8513 0 0 0 -2.22749</pose>
          <velocity>0 0 0 0 -0 0</velocity>
          <acceleration>0 0 0 0 -0 0</acceleration>
          <wrench>0 0 0 0 -0 0</wrench>
        </link>
        <link name='Wall_23'>
          <pose>12.2309 14.8955 0 0 -0 3.14159</pose>
          <velocity>0 0 0 0 -0 0</velocity>
          <acceleration>0 0 0 0 -0 0</acceleration>
          <wrench>0 0 0 0 -0 0</wrench>
        </link>
        <link name='Wall_24'>
          <pose>10.6163 13.9858 0 0 0 -2.30114</pose>
          <velocity>0 0 0 0 -0 0</velocity>
          <acceleration>0 0 0 0 -0 0</acceleration>
          <wrench>0 0 0 0 -0 0</wrench>
        </link>
        <link name='Wall_26'>
          <pose>9.80168 11.6512 0 0 0 -1.5708</pose>
          <velocity>0 0 0 0 -0 0</velocity>
          <acceleration>0 0 0 0 -0 0</acceleration>
          <wrench>0 0 0 0 -0 0</wrench>
        </link>
        <link name='Wall_27'>
          <pose>8.62668 10.2262 0 0 -0 3.14159</pose>
          <velocity>0 0 0 0 -0 0</velocity>
          <acceleration>0 0 0 0 -0 0</acceleration>
          <wrench>0 0 0 0 -0 0</wrench>
        </link>
        <link name='Wall_28'>
          <pose>6.15201 8.7054 0 0 0 -2.27796</pose>
          <velocity>0 0 0 0 -0 0</velocity>
          <acceleration>0 0 0 0 -0 0</acceleration>
          <wrench>0 0 0 0 -0 0</wrench>
        </link>
        <link name='Wall_29'>
          <pose>4.85688 4.321 0 0 0 -1.56921</pose>
          <velocity>0 0 0 0 -0 0</velocity>
          <acceleration>0 0 0 0 -0 0</acceleration>
          <wrench>0 0 0 0 -0 0</wrench>
        </link>
        <link name='Wall_30'>
          <pose>37.5103 1.4573 0 0 -0 0</pose>
          <velocity>0 0 0 0 -0 0</velocity>
          <acceleration>0 0 0 0 -0 0</acceleration>
          <wrench>0 0 0 0 -0 0</wrench>
        </link>
        <link name='Wall_32'>
          <pose>70.1853 -0.8427 0 0 0 -1.5708</pose>
          <velocity>0 0 0 0 -0 0</velocity>
          <acceleration>0 0 0 0 -0 0</acceleration>
          <wrench>0 0 0 0 -0 0</wrench>
        </link>
        <link name='Wall_34'>
          <pose>-58.3 -0.6939 0 0 0 -1.5708</pose>
          <velocity>0 0 0 0 -0 0</velocity>
          <acceleration>0 0 0 0 -0 0</acceleration>
          <wrench>0 0 0 0 -0 0</wrench>
        </link>
        <link name='Wall_35'>
          <pose>6 -3.1189 0 0 -0 0</pose>
          <velocity>0 0 0 0 -0 0</velocity>
          <acceleration>0 0 0 0 -0 0</acceleration>
          <wrench>0 0 0 0 -0 0</wrench>
        </link>
        <link name='Wall_37'>
          <pose>-31.9 43.0811 0 0 -0 0</pose>
          <velocity>0 0 0 0 -0 0</velocity>
          <acceleration>0 0 0 0 -0 0</acceleration>
          <wrench>0 0 0 0 -0 0</wrench>
        </link>
        <link name='Wall_41'>
          <pose>-29.4175 17.2738 0 0 -0 1.5708</pose>
          <velocity>0 0 0 0 -0 0</velocity>
          <acceleration>0 0 0 0 -0 0</acceleration>
          <wrench>0 0 0 0 -0 0</wrench>
        </link>
        <link name='Wall_43'>
          <pose>-14.4925 33.0738 0 0 -0 0</pose>
          <velocity>0 0 0 0 -0 0</velocity>
          <acceleration>0 0 0 0 -0 0</acceleration>
          <wrench>0 0 0 0 -0 0</wrench>
        </link>
        <link name='Wall_44'>
          <pose>0.43255 28.7738 0 0 0 -1.5708</pose>
          <velocity>0 0 0 0 -0 0</velocity>
          <acceleration>0 0 0 0 -0 0</acceleration>
          <wrench>0 0 0 0 -0 0</wrench>
        </link>
        <link name='Wall_45'>
          <pose>7.23255 24.4738 0 0 -0 0</pose>
          <velocity>0 0 0 0 -0 0</velocity>
          <acceleration>0 0 0 0 -0 0</acceleration>
          <wrench>0 0 0 0 -0 0</wrench>
        </link>
        <link name='Wall_46'>
          <pose>14.0326 23.4238 0 0 0 -1.5708</pose>
          <velocity>0 0 0 0 -0 0</velocity>
          <acceleration>0 0 0 0 -0 0</acceleration>
          <wrench>0 0 0 0 -0 0</wrench>
        </link>
        <link name='Wall_47'>
          <pose>8.89068 16.4593 0 0 0 -2.28642</pose>
          <velocity>0 0 0 0 -0 0</velocity>
          <acceleration>0 0 0 0 -0 0</acceleration>
          <wrench>0 0 0 0 -0 0</wrench>
        </link>
        <link name='Wall_5'>
          <pose>-34.2 22.4061 0 0 -0 1.5708</pose>
          <velocity>0 0 0 0 -0 0</velocity>
          <acceleration>0 0 0 0 -0 0</acceleration>
          <wrench>0 0 0 0 -0 0</wrench>
        </link>
        <link name='Wall_50'>
          <pose>3.3383 10.6547 0 0 -0 2.87979</pose>
          <velocity>0 0 0 0 -0 0</velocity>
          <acceleration>0 0 0 0 -0 0</acceleration>
          <wrench>0 0 0 0 -0 0</wrench>
        </link>
        <link name='Wall_51'>
          <pose>2.52779 10.0719 0 0 0 -2.0944</pose>
          <velocity>0 0 0 0 -0 0</velocity>
          <acceleration>0 0 0 0 -0 0</acceleration>
          <wrench>0 0 0 0 -0 0</wrench>
        </link>
        <link name='Wall_52'>
          <pose>2.60508 8.9018 0 0 0 -0.785398</pose>
          <velocity>0 0 0 0 -0 0</velocity>
          <acceleration>0 0 0 0 -0 0</acceleration>
          <wrench>0 0 0 0 -0 0</wrench>
        </link>
        <link name='Wall_53'>
          <pose>2.87025 8.2124 0 0 0 -2.35619</pose>
          <velocity>0 0 0 0 -0 0</velocity>
          <acceleration>0 0 0 0 -0 0</acceleration>
          <wrench>0 0 0 0 -0 0</wrench>
        </link>
        <link name='Wall_54'>
          <pose>2.35812 8.0002 0 0 -0 3.14159</pose>
          <velocity>0 0 0 0 -0 0</velocity>
          <acceleration>0 0 0 0 -0 0</acceleration>
          <wrench>0 0 0 0 -0 0</wrench>
        </link>
        <link name='Wall_55'>
          <pose>0.78808 4.7476 0 0 0 -1.94306</pose>
          <velocity>0 0 0 0 -0 0</velocity>
          <acceleration>0 0 0 0 -0 0</acceleration>
          <wrench>0 0 0 0 -0 0</wrench>
        </link>
        <link name='Wall_57'>
          <pose>-14.9925 1.4738 0 0 -0 0</pose>
          <velocity>0 0 0 0 -0 0</velocity>
          <acceleration>0 0 0 0 -0 0</acceleration>
          <wrench>0 0 0 0 -0 0</wrench>
        </link>
        <link name='Wall_9'>
          <pose>-29.4657 39.3427 0 0 0 -1.5708</pose>
          <velocity>0 0 0 0 -0 0</velocity>
          <acceleration>0 0 0 0 -0 0</acceleration>
          <wrench>0 0 0 0 -0 0</wrench>
        </link>
      </model>
      <model name='ground_plane'>
        <pose>0 0 0 0 -0 0</pose>
        <link name='link'>
          <pose>0 0 0 0 -0 0</pose>
          <velocity>0 0 0 0 -0 0</velocity>
          <acceleration>0 0 0 0 -0 0</acceleration>
          <wrench>0 0 0 0 -0 0</wrench>
        </link>
      </model>
      <model name='racecar'>
        <pose>5.2e-05 -0 0.049999 1.61322e-27 1e-06 -1e-05</pose>
        <link name='camera_link'>
          <pose>0.350052 -4e-06 0.099999 1.61322e-27 1e-06 -1e-05</pose>
          <velocity>0 -1e-06 5e-06 0 5e-06 0</velocity>
          <acceleration>-0 0 -0 0 -0 -3e-06</acceleration>
          <wrench>-0 0 -0 0 -0 0</wrench>
        </link>
        <link name='chassis'>
          <pose>5.2e-05 -0 0.049999 1.61322e-27 1e-06 -1e-05</pose>
          <velocity>0 -0 7e-06 7.94777e-29 5e-06 -1e-06</velocity>
          <acceleration>-0 0 -0 0 -0 0</acceleration>
          <wrench>-0 0 -0 0 -0 0</wrench>
        </link>
        <link name='hokuyo_link'>
          <pose>0.325052 -4e-06 0.114999 1.61322e-27 1e-06 -1e-05</pose>
          <velocity>1e-06 -1e-06 5e-06 -4.11785e-28 5e-06 -3e-06</velocity>
          <acceleration>-0 0 -0 0 -0 0</acceleration>
          <wrench>-0 0 -0 0 -0 0</wrench>
        </link>
        <link name='left_front_wheel'>
          <pose>0.325053 0.099996 0.049999 -1.58319 1.56993 3.13024</pose>
          <velocity>0 -0 -0 2e-06 5e-06 1e-06</velocity>
          <acceleration>-0 0 0 0 -0 0</acceleration>
          <wrench>-0 0 0 0 -0 0</wrench>
        </link>
        <link name='left_rear_wheel'>
          <pose>5.3e-05 0.1 0.049999 1.57079 0.001061 -1e-05</pose>
          <velocity>0 -0 7e-06 3e-06 6e-06 -6.72898e-28</velocity>
          <acceleration>-0 -0 0 0 2e-06 0</acceleration>
          <wrench>-0 -0 0 0 -0 0</wrench>
        </link>
        <link name='left_steering_hinge'>
          <pose>0.325053 0.099996 0.049999 2.1152 1.57078 2.11624</pose>
          <velocity>0 -0 5e-06 -4.1e-05 5e-06 1e-06</velocity>
          <acceleration>-0 0 0 0 -0 9e-06</acceleration>
          <wrench>-0 0 0 0 -0 0</wrench>
        </link>
        <link name='right_front_wheel'>
          <pose>0.325051 -0.100004 0.049999 -1.5643 1.56817 -3.13582</pose>
          <velocity>0 -1e-06 0 1.1e-05 7e-06 1e-06</velocity>
          <acceleration>0 0 0 0 2e-06 0</acceleration>
          <wrench>0 0 0 0 -0 0</wrench>
        </link>
        <link name='right_rear_wheel'>
          <pose>5.1e-05 -0.1 0.049999 1.5708 0.001024 -1e-05</pose>
          <velocity>0 -0 7e-06 3e-06 3e-06 -1.13596e-28</velocity>
          <acceleration>0 -0 -0 0 -4e-06 0</acceleration>
          <wrench>0 -0 -0 0 -0 0</wrench>
        </link>
        <link name='right_steering_hinge'>
          <pose>0.325051 -0.100004 0.049999 2.50416 1.57079 2.50345</pose>
          <velocity>0 -0 5e-06 -1.7e-05 5e-06 1e-06</velocity>
          <acceleration>0 0 -0 -0 -0 -7e-06</acceleration>
          <wrench>0 0 -0 0 -0 0</wrench>
        </link>
      </model>
    </state>
  </world>
</sdf>
